{{cpp/title|rethrow_exception}}
{{cpp/error/navbar}}
{{ddcla|header=exception|since=c++11|constexpr=c++26|
[[noreturn]] void rethrow_exception( std::exception_ptr p );
}}

抛出异常指针 {{c|p}} 所引用的先前捕获的异常对象，或其副本。

是否创建副本是未指定的。若创建副本，则以未指定的方式分配其存储。

若 {{c|p}} 为空则行为未定义。

===参数===
{{par begin}}
{{par|p|非空 {{lc|std::exception_ptr}}}}
{{par end}}

===异常===
若不创建副本，则为 {{c|p}} 所引用的异常对象。

否则，若实现成功复制异常对象，则为这种异常对象的副本。

否则，若分配或复制失败，则分别为 {{lc|std::bad_alloc}} 或复制异常对象时抛出的异常。

===注解===
在 {{wg21|P1675R2}} 前，{{tt|rethrow_exception}} 未被允许复制异常对象，这在一些异常对象分配在栈上的平台上无法实现。

{{ftm begin}}
{{ftm|__cpp_lib_constexpr_exceptions|value=202411L|std=C++26|{{c/core|constexpr}} 的异常类型}}
{{ftm end}}

===示例===
{{include|cpp/error/example exception_ptr}}

===参阅===
{{dsc begin}}
{{dsc inc|cpp/error/dsc exception_ptr}}
{{dsc inc|cpp/error/dsc current_exception}}
{{dsc end}}

{{langlinks|de|en|es|fr|it|ja|pt|ru}}