{{cpp/title|bad_function_call}}
{{cpp/utility/functional/navbar}}
{{ddcl|header=functional|
class bad_function_call;
}}

{{tt|std::bad_function_call}} 是当函数包装器无目标时 {{l2tt std|cpp/utility/functional/function/operator()}} 所抛出的异常类型。

{{inheritance diagram/std-bad_function_call}}

===成员函数===
{{cpp/error/exception/member of derived|bad_function_call|std=c++11}}

{{cpp/error/exception/inherit}}

===示例===
{{example
|code=
#include &lt;functional&gt;
#include &lt;iostream&gt;

int main()
{
    std::function&lt;int()&gt; f = nullptr;
    try
    {
        f();
    }
    catch (const std::bad_function_call&amp; e)
    {
        std::cout &lt;&lt; e.what() &lt;&lt; '\n';
    }
}
|p=true
|output=
bad function call
}}

===缺陷报告===
{{dr list begin}}
{{dr list item|wg=lwg|dr=2233|std=C++11|before={{tt|what()}} 始终会返回与 {{l2tf std|cpp/error/exception/what}} 相同的解释字符串|after=返回自己的解释字符串}}
{{dr list end}}

===参阅===
{{dsc begin}}
{{dsc inc|cpp/utility/functional/dsc function}}
{{dsc end}}

{{langlinks|de|en|es|fr|it|ja|pt|ru}}