{{cpp/title|future_error}}
{{cpp/thread/future_error/navbar}}
{{dcl begin}}
{{dcl header|future}}
{{dcl|since=c++11|
class future_error;
}}
{{dcl end}}

类 {{lc|std::future_error}} 定义异常对象，它由处理异步执行和共享状态（{{lc|std::future}}、{{lc|std::promise}} 等）的线程库中的函数在失败时抛出。同 {{lc|std::system_error}}，此异常携带与 {{lc|std::error_code}} 兼容的错误码。

{{inheritance diagram/std-future_error}}

===成员函数===
{{dsc begin}}
{{dsc inc|cpp/thread/future_error/dsc constructor}}
{{dsc inc|cpp/thread/future_error/dsc operator{{=}}}}
{{dsc inc|cpp/thread/future_error/dsc code}}
{{dsc inc|cpp/thread/future_error/dsc what}}
{{dsc end}}

{{inherited|[[cpp/error/logic_error|{{small|std::}}logic_error]]}}
{{cpp/error/exception/inherit}}

===示例===
{{example
|code=
#include &lt;future&gt;
#include &lt;iostream&gt;

int main()
{
    std::future&lt;int&gt; empty;
    try
    {
        int n = empty.get(); // 行为未定义，但一些实现抛出 std::future_error
    }
    catch (const std::future_error&amp; e)
    {
        std::cout &lt;&lt; "捕获了 future_error，其代码为 \"" &lt;&lt; e.code()
                  &lt;&lt; "\"\n消息: \"" &lt;&lt; e.what() &lt;&lt; "\"\n";
    }
}
|p=true
|output=
捕获了 future_error，其代码为 "future:3"
消息: "No associated state"
}}

===参阅===
{{dsc begin}}
{{dsc inc|cpp/thread/dsc future_errc}}
{{dsc end}}

{{langlinks|de|en|es|fr|it|ja|pt|ru}}